<?xml version="1.0"?>

<robot name="rob" xmlns:xacro="http://www.ros.org/wiki/xacro">

  <gazebo reference="caster">
  		<material> Gazebo/Blue </material>
  </gazebo>

  <gazebo reference="left_wheel">
  		<material> Gazebo/Red </material>
  </gazebo>

  <gazebo reference="right_wheel">
  		<material> Gazebo/Grey </material>
  </gazebo>

  <material name="blue">
    <color rgba="0 0 0.8 1"/>
  </material>

  <xacro:macro name="default_inertial" params="mass">
	  <inertial>
	    <mass value="${mass}" />
      	    <inertia ixx="1.0" ixy="0.0" ixz="0.0" iyy="1.0" iyz="0.0" izz="1.0" />
      </inertial>
  </xacro:macro>

	<xacro:macro name="wheel" params="suffix reflect">
	
		<link name="${suffix}_wheel">
			<xacro:default_inertial mass="1"/>

			<visual>
				<origin xyz="0 0 0" rpy="${-3.1415927/2} 0 0" />
				<geometry>
					<cylinder radius="0.15" length="0.1" />
				</geometry>
				<material name="blue"/>
			</visual>

			<collision>
				<origin xyz="0 0 0" rpy="${-3.1415927/2} 0 0" />
				<geometry>
					<cylinder radius="0.15" length="0.1" />
				</geometry>
			</collision>
		</link>

		<joint name="base_${suffix}_wheel_joint" type="continuous">
			<axis xyz="0 1 0" />
			<origin xyz="-0.17 ${reflect*0.23} 0.091" rpy="0 0 0" />
			<parent link="base_link" />
			<child link="${suffix}_wheel" />
			<dynamics damping="0.2" friction="0.1"/>
		</joint>

	</xacro:macro>


	<link name="base_link">
		<xacro:default_inertial mass="1"/>

		<visual>
			<origin xyz="-0.045 0 0.145" rpy="0 0 0" />
			<geometry>
				<mesh filename="package://urdf_hw/meshes/chassis.dae"/>
			</geometry>
		</visual>

		<collision>
			<origin xyz="-0.045 0 0.145" rpy="0 0 0" />
			<geometry>
				<mesh filename="package://urdf_hw/meshes/chassis.dae"/>
			</geometry>
		</collision>
	</link>

	<link name="caster">
		<xacro:default_inertial mass="1"/>

		<visual>
			<origin xyz="0 0 0" rpy="${-3.1415927/2.0} 0 0" />
			<geometry>
				<sphere radius="0.09"/>
			</geometry>
			<material name="blue"/>
		</visual>

		<collision>
			<origin xyz="0 0 0" rpy="${-3.1415927/2.0} 0 0" />
			<geometry>
				<sphere radius="0.09"/>
			</geometry>
		</collision>
	</link>

	<joint name="caster_joint" type="continuous">
		<axis xyz="0 1 0" />
		<origin xyz="0 0 -0.02" rpy="0 0 0" />
		<parent link="abc"/>
		<child link="caster"/>
		<dynamics damping="0.05" friction="0.02"/>
	</joint>

	<link name="abc">
		<xacro:default_inertial mass="1"/>

		<visual>
			<origin xyz="-0.6 0 0" rpy="0 0 0" />
			<geometry>
				<box size="0.01 0.01 0.01" />
			</geometry>
		</visual>

		<collision>
			<origin xyz="-0.6 0 0" rpy="0 0 0" />
			<geometry>
				<box size="0.01 0.01 0.01" />
			</geometry>
		</collision>
	</link>


	<joint name="base_abc_joint" type="revolute">
		<origin xyz="0.15 0 -0.02" rpy="0 0 0" />
		<axis xyz="0 0 1" />
		<parent link="base_link" />
		<child link="abc" />
		<limit effort="10" velocity="1.0" lower="-1.57" upper="1.57"/>
	</joint>

	<xacro:wheel suffix="left" reflect="1"/>
	<xacro:wheel suffix="right" reflect="-1"/>
	
	<link name="lidar_link">
    		<xacro:default_inertial mass="0.1"/>
    		<visual>
      			<origin xyz="0 0 0" rpy="0 0 0"/>
      			<geometry>
        			<cylinder radius="0.04" length="0.05"/>
      			</geometry>
      			<material name="blue"/>
    		</visual>
    		<collision>
      			<origin xyz="0 0 0" rpy="0 0 0"/>
      			<geometry>
        			<cylinder radius="0.04" length="0.05"/>
      			</geometry>
    		</collision>
  	</link>

  	<joint name="lidar_joint" type="fixed">
    		<parent link="base_link"/>
    		<child link="lidar_link"/>
    		<origin xyz="0.0 0 0.22" rpy="0 0 0"/>
  	</joint>

  	<gazebo reference="lidar_link">
    		<sensor type="ray" name="laser_sensor">
      			<pose>0 0 0 0 0 0</pose>
      			<update_rate>30</update_rate>
      			<ray>
        			<scan>
          				<horizontal>
            					<samples>360</samples>
            					<resolution>1</resolution>
            					<min_angle>-3.1415</min_angle>
            					<max_angle>3.1415</max_angle>
          				</horizontal>
        			</scan>
        			<range>
          				<min>0.12</min>
          				<max>3.5</max>
          				<resolution>0.01</resolution>
        			</range>
        			<noise>
          				<type>gaussian</type>
          				<mean>0.0</mean>
          				<stddev>0.005</stddev>
        			</noise>
      			</ray>
      			<plugin name="gazebo_ros_laser_controller" filename="libgazebo_ros_laser.so">
        			<topicName>scan</topicName>
        			<frameName>lidar_link</frameName>
      			</plugin>
    		</sensor>
  	</gazebo>
  	
  	<link name="bumper_link">
    		<xacro:default_inertial mass="0.1"/>
    		<visual>
      			<origin xyz="0 0 0" rpy="0 0 0"/>
      			<geometry>
        			<box size="0.2 0.05 0.05"/>
      			</geometry>
      			<material name="blue"/>
    		</visual>
    		<collision name="bumper_collision">
      			<origin xyz="0 0 0" rpy="0 0 0"/>
      			<geometry>
        			<box size="0.2 0.05 0.05"/>
      			</geometry>
    		</collision>
  	</link>

  	<joint name="bumper_joint" type="fixed">
    		<parent link="base_link"/>
    		<child link="bumper_link"/>
    		<origin xyz="0.25 0 0.1" rpy="0 0 0"/>
  	</joint>

  	<gazebo reference="bumper_link">
  		<sensor type="contact" name="bumper_sensor">
    			<always_on>true</always_on>
    			<update_rate>50</update_rate>
    			<contact>
      				<collision>bumper_collision</collision>
    			</contact>
    			<plugin name="bumper_plugin" filename="libgazebo_ros_bumper.so">
      				<alwaysOn>true</alwaysOn>
      				<updateRate>50.0</updateRate>
      				<robotNamespace>/</robotNamespace>
      				<bodyName>bumper_link</bodyName>
      				<topicName>bumper_sensor</topicName>
      				<frameName>bumper_link</frameName>
    			</plugin>
  		</sensor>
	</gazebo>


  	<transmission name="trans_left_wheel">
  		<type>transmission_interface/SimpleTransmission</type>
  		<joint name="base_left_wheel_joint">
    			<hardwareInterface>EffortJointInterface</hardwareInterface>
  		</joint>
  		<actuator name="left_wheel_motor">
    			<hardwareInterface>EffortJointInterface</hardwareInterface>
    			<mechanicalReduction>1</mechanicalReduction>
  		</actuator>
	</transmission>
	
	<transmission name="trans_right_wheel">
  		<type>transmission_interface/SimpleTransmission</type>
  		<joint name="base_right_wheel_joint">
    			<hardwareInterface>EffortJointInterface</hardwareInterface>
  		</joint>
  		<actuator name="right_wheel_motor">
    			<hardwareInterface>EffortJointInterface</hardwareInterface>
    			<mechanicalReduction>1</mechanicalReduction>
  		</actuator>
	</transmission>
	
	<transmission name="trans_caster">
  		<type>transmission_interface/SimpleTransmission</type>
  		<joint name="caster_joint">
    			<hardwareInterface>EffortJointInterface</hardwareInterface>
  		</joint>
  		<actuator name="caster_motor">
    			<hardwareInterface>EffortJointInterface</hardwareInterface>
    			<mechanicalReduction>1</mechanicalReduction>
  		</actuator>
	</transmission>
	
	<gazebo>
  		<plugin name="gazebo_ros_control" filename="libgazebo_ros_control.so">
    			<robotNamespace>/</robotNamespace>	
  		</plugin>
	</gazebo>
	
	<transmission name="trans_front_wheel">
  		<type>transmission_interface/SimpleTransmission</type>
  		<joint name="base_abc_joint">
    			<hardwareInterface>EffortJointInterface</hardwareInterface>
  		</joint>
  		<actuator name="front_wheel_motor">
    			<hardwareInterface>EffortJointInterface</hardwareInterface>
    			<mechanicalReduction>1.0</mechanicalReduction>
  		</actuator>
	</transmission>
</robot>
